[2020-09-15 10:55:54,410: ERROR/MainProcess] consumer: Cannot connect to redis://localhost:6379//: Error 10061 connecting to localhost:6379. [WinError 10061] No connection could be made because the target machine actively refused it...
Trying again in 2.00 seconds... (1/100)

[2020-09-15 10:56:00,435: ERROR/MainProcess] consumer: Cannot connect to redis://localhost:6379//: Error 10061 connecting to localhost:6379. [WinError 10061] No connection could be made because the target machine actively refused it...
Trying again in 4.00 seconds... (2/100)

[2020-09-15 10:56:08,446: ERROR/MainProcess] consumer: Cannot connect to redis://localhost:6379//: Error 10061 connecting to localhost:6379. [WinError 10061] No connection could be made because the target machine actively refused it...
Trying again in 6.00 seconds... (3/100)

[2020-09-15 10:56:18,495: ERROR/MainProcess] consumer: Cannot connect to redis://localhost:6379//: Error 10061 connecting to localhost:6379. [WinError 10061] No connection could be made because the target machine actively refused it...
Trying again in 8.00 seconds... (4/100)

[2020-09-15 10:56:30,519: ERROR/MainProcess] consumer: Cannot connect to redis://localhost:6379//: Error 10061 connecting to localhost:6379. [WinError 10061] No connection could be made because the target machine actively refused it...
Trying again in 10.00 seconds... (5/100)

[2020-09-15 10:56:44,551: ERROR/MainProcess] consumer: Cannot connect to redis://localhost:6379//: Error 10061 connecting to localhost:6379. [WinError 10061] No connection could be made because the target machine actively refused it...
Trying again in 12.00 seconds... (6/100)

[2020-09-15 10:57:00,576: ERROR/MainProcess] consumer: Cannot connect to redis://localhost:6379//: Error 10061 connecting to localhost:6379. [WinError 10061] No connection could be made because the target machine actively refused it...
Trying again in 14.00 seconds... (7/100)

[2020-09-15 10:57:18,602: ERROR/MainProcess] consumer: Cannot connect to redis://localhost:6379//: Error 10061 connecting to localhost:6379. [WinError 10061] No connection could be made because the target machine actively refused it...
Trying again in 16.00 seconds... (8/100)

[2020-09-15 10:57:38,639: ERROR/MainProcess] consumer: Cannot connect to redis://localhost:6379//: Error 10061 connecting to localhost:6379. [WinError 10061] No connection could be made because the target machine actively refused it...
Trying again in 18.00 seconds... (9/100)

[2020-09-15 10:58:00,664: ERROR/MainProcess] consumer: Cannot connect to redis://localhost:6379//: Error 10061 connecting to localhost:6379. [WinError 10061] No connection could be made because the target machine actively refused it...
Trying again in 20.00 seconds... (10/100)

[2020-09-15 10:58:24,692: ERROR/MainProcess] consumer: Cannot connect to redis://localhost:6379//: Error 10061 connecting to localhost:6379. [WinError 10061] No connection could be made because the target machine actively refused it...
Trying again in 22.00 seconds... (11/100)

[2020-09-15 10:58:50,712: ERROR/MainProcess] consumer: Cannot connect to redis://localhost:6379//: Error 10061 connecting to localhost:6379. [WinError 10061] No connection could be made because the target machine actively refused it...
Trying again in 24.00 seconds... (12/100)

[2020-09-15 10:59:18,734: ERROR/MainProcess] consumer: Cannot connect to redis://localhost:6379//: Error 10061 connecting to localhost:6379. [WinError 10061] No connection could be made because the target machine actively refused it...
Trying again in 26.00 seconds... (13/100)

[2020-09-15 10:59:48,772: ERROR/MainProcess] consumer: Cannot connect to redis://localhost:6379//: Error 10061 connecting to localhost:6379. [WinError 10061] No connection could be made because the target machine actively refused it...
Trying again in 28.00 seconds... (14/100)

[2020-09-15 11:00:20,811: ERROR/MainProcess] consumer: Cannot connect to redis://localhost:6379//: Error 10061 connecting to localhost:6379. [WinError 10061] No connection could be made because the target machine actively refused it...
Trying again in 30.00 seconds... (15/100)

[2020-09-15 11:00:54,850: ERROR/MainProcess] consumer: Cannot connect to redis://localhost:6379//: Error 10061 connecting to localhost:6379. [WinError 10061] No connection could be made because the target machine actively refused it...
Trying again in 32.00 seconds... (16/100)

[2020-09-15 11:01:28,883: INFO/MainProcess] Connected to redis://localhost:6379//
[2020-09-15 11:01:30,910: INFO/MainProcess] mingle: searching for neighbors
[2020-09-15 11:06:11,919: INFO/MainProcess] Connected to redis://localhost:6379//
[2020-09-15 11:06:13,947: INFO/MainProcess] mingle: searching for neighbors
[2020-09-15 11:06:21,094: CRITICAL/MainProcess] Unrecoverable error: ResponseError("wrong number of arguments for 'set' command")
Traceback (most recent call last):
  File "c:\users\zikza\appdata\local\programs\python\python38-32\lib\site-packages\celery\worker\worker.py", line 208, in start
    self.blueprint.start(self)
  File "c:\users\zikza\appdata\local\programs\python\python38-32\lib\site-packages\celery\bootsteps.py", line 119, in start
    step.start(parent)
  File "c:\users\zikza\appdata\local\programs\python\python38-32\lib\site-packages\celery\bootsteps.py", line 369, in start
    return self.obj.start()
  File "c:\users\zikza\appdata\local\programs\python\python38-32\lib\site-packages\celery\worker\consumer\consumer.py", line 318, in start
    blueprint.start(self)
  File "c:\users\zikza\appdata\local\programs\python\python38-32\lib\site-packages\celery\bootsteps.py", line 119, in start
    step.start(parent)
  File "c:\users\zikza\appdata\local\programs\python\python38-32\lib\site-packages\celery\worker\consumer\mingle.py", line 40, in start
    self.sync(c)
  File "c:\users\zikza\appdata\local\programs\python\python38-32\lib\site-packages\celery\worker\consumer\mingle.py", line 44, in sync
    replies = self.send_hello(c)
  File "c:\users\zikza\appdata\local\programs\python\python38-32\lib\site-packages\celery\worker\consumer\mingle.py", line 57, in send_hello
    replies = inspect.hello(c.hostname, our_revoked._data) or {}
  File "c:\users\zikza\appdata\local\programs\python\python38-32\lib\site-packages\celery\app\control.py", line 156, in hello
    return self._request('hello', from_node=from_node, revoked=revoked)
  File "c:\users\zikza\appdata\local\programs\python\python38-32\lib\site-packages\celery\app\control.py", line 98, in _request
    return self._prepare(self.app.control.broadcast(
  File "c:\users\zikza\appdata\local\programs\python\python38-32\lib\site-packages\celery\app\control.py", line 478, in broadcast
    return self.mailbox(conn)._broadcast(
  File "c:\users\zikza\appdata\local\programs\python\python38-32\lib\site-packages\kombu\pidbox.py", line 349, in _broadcast
    return self._collect(reply_ticket, limit=limit,
  File "c:\users\zikza\appdata\local\programs\python\python38-32\lib\site-packages\kombu\pidbox.py", line 391, in _collect
    self.connection.drain_events(timeout=timeout)
  File "c:\users\zikza\appdata\local\programs\python\python38-32\lib\site-packages\kombu\connection.py", line 324, in drain_events
    return self.transport.drain_events(self.connection, **kwargs)
  File "c:\users\zikza\appdata\local\programs\python\python38-32\lib\site-packages\kombu\transport\virtual\base.py", line 963, in drain_events
    get(self._deliver, timeout=timeout)
  File "c:\users\zikza\appdata\local\programs\python\python38-32\lib\site-packages\kombu\transport\redis.py", line 381, in get
    self.maybe_restore_messages()
  File "c:\users\zikza\appdata\local\programs\python\python38-32\lib\site-packages\kombu\transport\redis.py", line 339, in maybe_restore_messages
    return channel.qos.restore_visible(
  File "c:\users\zikza\appdata\local\programs\python\python38-32\lib\site-packages\kombu\transport\redis.py", line 196, in restore_visible
    with Mutex(client, self.unacked_mutex_key,
  File "c:\users\zikza\appdata\local\programs\python\python38-32\lib\contextlib.py", line 113, in __enter__
    return next(self.gen)
  File "c:\users\zikza\appdata\local\programs\python\python38-32\lib\site-packages\kombu\transport\redis.py", line 117, in Mutex
    lock_acquired = lock.acquire(blocking=False)
  File "c:\users\zikza\appdata\local\programs\python\python38-32\lib\site-packages\redis\lock.py", line 182, in acquire
    if self.do_acquire(token):
  File "c:\users\zikza\appdata\local\programs\python\python38-32\lib\site-packages\redis\lock.py", line 197, in do_acquire
    if self.redis.set(self.name, token, nx=True, px=timeout):
  File "c:\users\zikza\appdata\local\programs\python\python38-32\lib\site-packages\redis\client.py", line 1766, in set
    return self.execute_command('SET', *pieces)
  File "c:\users\zikza\appdata\local\programs\python\python38-32\lib\site-packages\redis\client.py", line 878, in execute_command
    return self.parse_response(conn, command_name, **options)
  File "c:\users\zikza\appdata\local\programs\python\python38-32\lib\site-packages\redis\client.py", line 892, in parse_response
    response = connection.read_response()
  File "c:\users\zikza\appdata\local\programs\python\python38-32\lib\site-packages\redis\connection.py", line 752, in read_response
    raise response
redis.exceptions.ResponseError: wrong number of arguments for 'set' command
[2020-09-15 11:08:20,937: INFO/MainProcess] Connected to redis://localhost:6379//
[2020-09-15 11:08:22,967: INFO/MainProcess] mingle: searching for neighbors
[2020-09-15 11:08:30,045: CRITICAL/MainProcess] Unrecoverable error: ResponseError("wrong number of arguments for 'set' command")
Traceback (most recent call last):
  File "c:\users\zikza\appdata\local\programs\python\python38-32\lib\site-packages\celery\worker\worker.py", line 208, in start
    self.blueprint.start(self)
  File "c:\users\zikza\appdata\local\programs\python\python38-32\lib\site-packages\celery\bootsteps.py", line 119, in start
    step.start(parent)
  File "c:\users\zikza\appdata\local\programs\python\python38-32\lib\site-packages\celery\bootsteps.py", line 369, in start
    return self.obj.start()
  File "c:\users\zikza\appdata\local\programs\python\python38-32\lib\site-packages\celery\worker\consumer\consumer.py", line 318, in start
    blueprint.start(self)
  File "c:\users\zikza\appdata\local\programs\python\python38-32\lib\site-packages\celery\bootsteps.py", line 119, in start
    step.start(parent)
  File "c:\users\zikza\appdata\local\programs\python\python38-32\lib\site-packages\celery\worker\consumer\mingle.py", line 40, in start
    self.sync(c)
  File "c:\users\zikza\appdata\local\programs\python\python38-32\lib\site-packages\celery\worker\consumer\mingle.py", line 44, in sync
    replies = self.send_hello(c)
  File "c:\users\zikza\appdata\local\programs\python\python38-32\lib\site-packages\celery\worker\consumer\mingle.py", line 57, in send_hello
    replies = inspect.hello(c.hostname, our_revoked._data) or {}
  File "c:\users\zikza\appdata\local\programs\python\python38-32\lib\site-packages\celery\app\control.py", line 156, in hello
    return self._request('hello', from_node=from_node, revoked=revoked)
  File "c:\users\zikza\appdata\local\programs\python\python38-32\lib\site-packages\celery\app\control.py", line 98, in _request
    return self._prepare(self.app.control.broadcast(
  File "c:\users\zikza\appdata\local\programs\python\python38-32\lib\site-packages\celery\app\control.py", line 478, in broadcast
    return self.mailbox(conn)._broadcast(
  File "c:\users\zikza\appdata\local\programs\python\python38-32\lib\site-packages\kombu\pidbox.py", line 349, in _broadcast
    return self._collect(reply_ticket, limit=limit,
  File "c:\users\zikza\appdata\local\programs\python\python38-32\lib\site-packages\kombu\pidbox.py", line 391, in _collect
    self.connection.drain_events(timeout=timeout)
  File "c:\users\zikza\appdata\local\programs\python\python38-32\lib\site-packages\kombu\connection.py", line 324, in drain_events
    return self.transport.drain_events(self.connection, **kwargs)
  File "c:\users\zikza\appdata\local\programs\python\python38-32\lib\site-packages\kombu\transport\virtual\base.py", line 963, in drain_events
    get(self._deliver, timeout=timeout)
  File "c:\users\zikza\appdata\local\programs\python\python38-32\lib\site-packages\kombu\transport\redis.py", line 381, in get
    self.maybe_restore_messages()
  File "c:\users\zikza\appdata\local\programs\python\python38-32\lib\site-packages\kombu\transport\redis.py", line 339, in maybe_restore_messages
    return channel.qos.restore_visible(
  File "c:\users\zikza\appdata\local\programs\python\python38-32\lib\site-packages\kombu\transport\redis.py", line 196, in restore_visible
    with Mutex(client, self.unacked_mutex_key,
  File "c:\users\zikza\appdata\local\programs\python\python38-32\lib\contextlib.py", line 113, in __enter__
    return next(self.gen)
  File "c:\users\zikza\appdata\local\programs\python\python38-32\lib\site-packages\kombu\transport\redis.py", line 117, in Mutex
    lock_acquired = lock.acquire(blocking=False)
  File "c:\users\zikza\appdata\local\programs\python\python38-32\lib\site-packages\redis\lock.py", line 182, in acquire
    if self.do_acquire(token):
  File "c:\users\zikza\appdata\local\programs\python\python38-32\lib\site-packages\redis\lock.py", line 197, in do_acquire
    if self.redis.set(self.name, token, nx=True, px=timeout):
  File "c:\users\zikza\appdata\local\programs\python\python38-32\lib\site-packages\redis\client.py", line 1766, in set
    return self.execute_command('SET', *pieces)
  File "c:\users\zikza\appdata\local\programs\python\python38-32\lib\site-packages\redis\client.py", line 878, in execute_command
    return self.parse_response(conn, command_name, **options)
  File "c:\users\zikza\appdata\local\programs\python\python38-32\lib\site-packages\redis\client.py", line 892, in parse_response
    response = connection.read_response()
  File "c:\users\zikza\appdata\local\programs\python\python38-32\lib\site-packages\redis\connection.py", line 752, in read_response
    raise response
redis.exceptions.ResponseError: wrong number of arguments for 'set' command
[2020-09-15 11:30:38,143: INFO/MainProcess] Connected to redis://localhost:6379//
[2020-09-15 11:30:40,176: INFO/MainProcess] mingle: searching for neighbors
[2020-09-15 11:30:47,252: CRITICAL/MainProcess] Unrecoverable error: ResponseError("wrong number of arguments for 'set' command")
Traceback (most recent call last):
  File "c:\users\zikza\appdata\local\programs\python\python38-32\lib\site-packages\celery\worker\worker.py", line 208, in start
    self.blueprint.start(self)
  File "c:\users\zikza\appdata\local\programs\python\python38-32\lib\site-packages\celery\bootsteps.py", line 119, in start
    step.start(parent)
  File "c:\users\zikza\appdata\local\programs\python\python38-32\lib\site-packages\celery\bootsteps.py", line 369, in start
    return self.obj.start()
  File "c:\users\zikza\appdata\local\programs\python\python38-32\lib\site-packages\celery\worker\consumer\consumer.py", line 318, in start
    blueprint.start(self)
  File "c:\users\zikza\appdata\local\programs\python\python38-32\lib\site-packages\celery\bootsteps.py", line 119, in start
    step.start(parent)
  File "c:\users\zikza\appdata\local\programs\python\python38-32\lib\site-packages\celery\worker\consumer\mingle.py", line 40, in start
    self.sync(c)
  File "c:\users\zikza\appdata\local\programs\python\python38-32\lib\site-packages\celery\worker\consumer\mingle.py", line 44, in sync
    replies = self.send_hello(c)
  File "c:\users\zikza\appdata\local\programs\python\python38-32\lib\site-packages\celery\worker\consumer\mingle.py", line 57, in send_hello
    replies = inspect.hello(c.hostname, our_revoked._data) or {}
  File "c:\users\zikza\appdata\local\programs\python\python38-32\lib\site-packages\celery\app\control.py", line 156, in hello
    return self._request('hello', from_node=from_node, revoked=revoked)
  File "c:\users\zikza\appdata\local\programs\python\python38-32\lib\site-packages\celery\app\control.py", line 98, in _request
    return self._prepare(self.app.control.broadcast(
  File "c:\users\zikza\appdata\local\programs\python\python38-32\lib\site-packages\celery\app\control.py", line 478, in broadcast
    return self.mailbox(conn)._broadcast(
  File "c:\users\zikza\appdata\local\programs\python\python38-32\lib\site-packages\kombu\pidbox.py", line 349, in _broadcast
    return self._collect(reply_ticket, limit=limit,
  File "c:\users\zikza\appdata\local\programs\python\python38-32\lib\site-packages\kombu\pidbox.py", line 391, in _collect
    self.connection.drain_events(timeout=timeout)
  File "c:\users\zikza\appdata\local\programs\python\python38-32\lib\site-packages\kombu\connection.py", line 324, in drain_events
    return self.transport.drain_events(self.connection, **kwargs)
  File "c:\users\zikza\appdata\local\programs\python\python38-32\lib\site-packages\kombu\transport\virtual\base.py", line 963, in drain_events
    get(self._deliver, timeout=timeout)
  File "c:\users\zikza\appdata\local\programs\python\python38-32\lib\site-packages\kombu\transport\redis.py", line 381, in get
    self.maybe_restore_messages()
  File "c:\users\zikza\appdata\local\programs\python\python38-32\lib\site-packages\kombu\transport\redis.py", line 339, in maybe_restore_messages
    return channel.qos.restore_visible(
  File "c:\users\zikza\appdata\local\programs\python\python38-32\lib\site-packages\kombu\transport\redis.py", line 196, in restore_visible
    with Mutex(client, self.unacked_mutex_key,
  File "c:\users\zikza\appdata\local\programs\python\python38-32\lib\contextlib.py", line 113, in __enter__
    return next(self.gen)
  File "c:\users\zikza\appdata\local\programs\python\python38-32\lib\site-packages\kombu\transport\redis.py", line 117, in Mutex
    lock_acquired = lock.acquire(blocking=False)
  File "c:\users\zikza\appdata\local\programs\python\python38-32\lib\site-packages\redis\lock.py", line 182, in acquire
    if self.do_acquire(token):
  File "c:\users\zikza\appdata\local\programs\python\python38-32\lib\site-packages\redis\lock.py", line 197, in do_acquire
    if self.redis.set(self.name, token, nx=True, px=timeout):
  File "c:\users\zikza\appdata\local\programs\python\python38-32\lib\site-packages\redis\client.py", line 1766, in set
    return self.execute_command('SET', *pieces)
  File "c:\users\zikza\appdata\local\programs\python\python38-32\lib\site-packages\redis\client.py", line 878, in execute_command
    return self.parse_response(conn, command_name, **options)
  File "c:\users\zikza\appdata\local\programs\python\python38-32\lib\site-packages\redis\client.py", line 892, in parse_response
    response = connection.read_response()
  File "c:\users\zikza\appdata\local\programs\python\python38-32\lib\site-packages\redis\connection.py", line 752, in read_response
    raise response
redis.exceptions.ResponseError: wrong number of arguments for 'set' command
